package goldenfoods.world.gen;

import goldenfoods.registry.ModBlock;
import net.minecraft.block.Block;
import net.minecraft.world.World;

public class AppleTree
{
	public void generateSurface(World world, int i, int j, int k)
	{
		i = i - 5;
		j = j + 1;
		k = k - 5;

		world.setBlock(i+5, j+0, k+5, Block.getBlockById(17), 0, 2);
		world.setBlock(i+5, j+1, k+5, Block.getBlockById(17), 0, 2);
		world.setBlock(i+5, j+2, k+5, Block.getBlockById(17), 0, 2);
		world.setBlock(i+5, j+3, k+5, Block.getBlockById(17), 0, 2);
		world.setBlock(i+5, j+4, k+5, Block.getBlockById(17), 0, 2);
		world.setBlock(i+0, j+5, k+0, ModBlock.appleTreeLeaves, 0, 0);
		world.setBlock(i+1, j+5, k+0, ModBlock.appleTreeLeaves, 0, 0);
		world.setBlock(i+2, j+5, k+0, ModBlock.appleTreeLeaves, 0, 0);
		world.setBlock(i+3, j+5, k+0, ModBlock.appleTreeLeaves, 0, 0);
		world.setBlock(i+4, j+5, k+0, ModBlock.appleTreeLeaves, 0, 0);
		world.setBlock(i+5, j+5, k+0, ModBlock.appleTreeLeaves, 0, 0);
		world.setBlock(i+6, j+5, k+0, ModBlock.appleTreeLeaves, 0, 0);
		world.setBlock(i+7, j+5, k+0, ModBlock.appleTreeLeaves, 0, 0);
		world.setBlock(i+8, j+5, k+0, ModBlock.appleTreeLeaves, 0, 0);
		world.setBlock(i+9, j+5, k+0, ModBlock.appleTreeLeaves, 0, 0);
		world.setBlock(i+10, j+5, k+0, ModBlock.appleTreeLeaves, 0, 0);
		world.setBlock(i+0, j+5, k+1, ModBlock.appleTreeLeaves, 0, 0);
		world.setBlock(i+1, j+5, k+1, ModBlock.appleTreeLeaves, 0, 0);
		world.setBlock(i+2, j+5, k+1, ModBlock.appleTreeLeaves, 0, 0);
		world.setBlock(i+3, j+5, k+1, ModBlock.appleTreeLeaves, 0, 0);
		world.setBlock(i+4, j+5, k+1, ModBlock.appleTreeLeaves, 0, 0);
		world.setBlock(i+5, j+5, k+1, Block.getBlockById(17), 8, 2);
		world.setBlock(i+6, j+5, k+1, ModBlock.appleTreeLeaves, 0, 0);
		world.setBlock(i+7, j+5, k+1, ModBlock.appleTreeLeaves, 0, 0);
		world.setBlock(i+8, j+5, k+1, ModBlock.appleTreeLeaves, 0, 0);
		world.setBlock(i+9, j+5, k+1, ModBlock.appleTreeLeaves, 0, 0);
		world.setBlock(i+10, j+5, k+1, ModBlock.appleTreeLeaves, 0, 0);
		world.setBlock(i+0, j+5, k+2, ModBlock.appleTreeLeaves, 0, 0);
		world.setBlock(i+1, j+5, k+2, ModBlock.appleTreeLeaves, 0, 0);
		world.setBlock(i+2, j+5, k+2, ModBlock.appleTreeLeaves, 0, 0);
		world.setBlock(i+3, j+5, k+2, ModBlock.appleTreeLeaves, 0, 0);
		world.setBlock(i+4, j+5, k+2, ModBlock.appleTreeLeaves, 0, 0);
		world.setBlock(i+5, j+5, k+2, Block.getBlockById(17), 8, 2);
		world.setBlock(i+6, j+5, k+2, ModBlock.appleTreeLeaves, 0, 0);
		world.setBlock(i+7, j+5, k+2, ModBlock.appleTreeLeaves, 0, 0);
		world.setBlock(i+8, j+5, k+2, ModBlock.appleTreeLeaves, 0, 0);
		world.setBlock(i+9, j+5, k+2, ModBlock.appleTreeLeaves, 0, 0);
		world.setBlock(i+10, j+5, k+2, ModBlock.appleTreeLeaves, 0, 0);
		world.setBlock(i+0, j+5, k+3, ModBlock.appleTreeLeaves, 0, 0);
		world.setBlock(i+1, j+5, k+3, ModBlock.appleTreeLeaves, 0, 0);
		world.setBlock(i+2, j+5, k+3, ModBlock.appleTreeLeaves, 0, 0);
		world.setBlock(i+3, j+5, k+3, ModBlock.appleTreeLeaves, 0, 0);
		world.setBlock(i+4, j+5, k+3, ModBlock.appleTreeLeaves, 0, 0);
		world.setBlock(i+5, j+5, k+3, Block.getBlockById(17), 8, 2);
		world.setBlock(i+6, j+5, k+3, ModBlock.appleTreeLeaves, 0, 0);
		world.setBlock(i+7, j+5, k+3, ModBlock.appleTreeLeaves, 0, 0);
		world.setBlock(i+8, j+5, k+3, ModBlock.appleTreeLeaves, 0, 0);
		world.setBlock(i+9, j+5, k+3, ModBlock.appleTreeLeaves, 0, 0);
		world.setBlock(i+10, j+5, k+3, ModBlock.appleTreeLeaves, 0, 0);
		world.setBlock(i+0, j+5, k+4, ModBlock.appleTreeLeaves, 0, 0);
		world.setBlock(i+1, j+5, k+4, ModBlock.appleTreeLeaves, 0, 0);
		world.setBlock(i+2, j+5, k+4, ModBlock.appleTreeLeaves, 0, 0);
		world.setBlock(i+3, j+5, k+4, ModBlock.appleTreeLeaves, 0, 0);
		world.setBlock(i+4, j+5, k+4, ModBlock.appleTreeLeaves, 0, 0);
		world.setBlock(i+5, j+5, k+4, Block.getBlockById(17), 8, 2);
		world.setBlock(i+6, j+5, k+4, ModBlock.appleTreeLeaves, 0, 0);
		world.setBlock(i+7, j+5, k+4, ModBlock.appleTreeLeaves, 0, 0);
		world.setBlock(i+8, j+5, k+4, ModBlock.appleTreeLeaves, 0, 0);
		world.setBlock(i+9, j+5, k+4, ModBlock.appleTreeLeaves, 0, 0);
		world.setBlock(i+10, j+5, k+4, ModBlock.appleTreeLeaves, 0, 0);
		world.setBlock(i+0, j+5, k+5, ModBlock.appleTreeLeaves, 0, 0);
		world.setBlock(i+1, j+5, k+5, Block.getBlockById(17), 4, 2);
		world.setBlock(i+2, j+5, k+5, Block.getBlockById(17), 4, 2);
		world.setBlock(i+3, j+5, k+5, Block.getBlockById(17), 4, 2);
		world.setBlock(i+4, j+5, k+5, Block.getBlockById(17), 4, 2);
		world.setBlock(i+5, j+5, k+5, Block.getBlockById(17), 8, 2);
		world.setBlock(i+6, j+5, k+5, Block.getBlockById(17), 4, 2);
		world.setBlock(i+7, j+5, k+5, Block.getBlockById(17), 4, 2);
		world.setBlock(i+8, j+5, k+5, Block.getBlockById(17), 4, 2);
		world.setBlock(i+9, j+5, k+5, Block.getBlockById(17), 4, 2);
		world.setBlock(i+10, j+5, k+5, ModBlock.appleTreeLeaves, 0, 0);
		world.setBlock(i+0, j+5, k+6, ModBlock.appleTreeLeaves, 0, 0);
		world.setBlock(i+1, j+5, k+6, ModBlock.appleTreeLeaves, 0, 0);
		world.setBlock(i+2, j+5, k+6, ModBlock.appleTreeLeaves, 0, 0);
		world.setBlock(i+3, j+5, k+6, ModBlock.appleTreeLeaves, 0, 0);
		world.setBlock(i+4, j+5, k+6, ModBlock.appleTreeLeaves, 0, 0);
		world.setBlock(i+5, j+5, k+6, Block.getBlockById(17), 8, 2);
		world.setBlock(i+6, j+5, k+6, ModBlock.appleTreeLeaves, 0, 0);
		world.setBlock(i+7, j+5, k+6, ModBlock.appleTreeLeaves, 0, 0);
		world.setBlock(i+8, j+5, k+6, ModBlock.appleTreeLeaves, 0, 0);
		world.setBlock(i+9, j+5, k+6, ModBlock.appleTreeLeaves, 0, 0);
		world.setBlock(i+10, j+5, k+6, ModBlock.appleTreeLeaves, 0, 0);
		world.setBlock(i+0, j+5, k+7, ModBlock.appleTreeLeaves, 0, 0);
		world.setBlock(i+1, j+5, k+7, ModBlock.appleTreeLeaves, 0, 0);
		world.setBlock(i+2, j+5, k+7, ModBlock.appleTreeLeaves, 0, 0);
		world.setBlock(i+3, j+5, k+7, ModBlock.appleTreeLeaves, 0, 0);
		world.setBlock(i+4, j+5, k+7, ModBlock.appleTreeLeaves, 0, 0);
		world.setBlock(i+5, j+5, k+7, Block.getBlockById(17), 8, 2);
		world.setBlock(i+6, j+5, k+7, ModBlock.appleTreeLeaves, 0, 0);
		world.setBlock(i+7, j+5, k+7, ModBlock.appleTreeLeaves, 0, 0);
		world.setBlock(i+8, j+5, k+7, ModBlock.appleTreeLeaves, 0, 0);
		world.setBlock(i+9, j+5, k+7, ModBlock.appleTreeLeaves, 0, 0);
		world.setBlock(i+10, j+5, k+7, ModBlock.appleTreeLeaves, 0, 0);
		world.setBlock(i+0, j+5, k+8, ModBlock.appleTreeLeaves, 0, 0);
		world.setBlock(i+1, j+5, k+8, ModBlock.appleTreeLeaves, 0, 0);
		world.setBlock(i+2, j+5, k+8, ModBlock.appleTreeLeaves, 0, 0);
		world.setBlock(i+3, j+5, k+8, ModBlock.appleTreeLeaves, 0, 0);
		world.setBlock(i+4, j+5, k+8, ModBlock.appleTreeLeaves, 0, 0);
		world.setBlock(i+5, j+5, k+8, Block.getBlockById(17), 8, 2);
		world.setBlock(i+6, j+5, k+8, ModBlock.appleTreeLeaves, 0, 0);
		world.setBlock(i+7, j+5, k+8, ModBlock.appleTreeLeaves, 0, 0);
		world.setBlock(i+8, j+5, k+8, ModBlock.appleTreeLeaves, 0, 0);
		world.setBlock(i+9, j+5, k+8, ModBlock.appleTreeLeaves, 0, 0);
		world.setBlock(i+10, j+5, k+8, ModBlock.appleTreeLeaves, 0, 0);
		world.setBlock(i+0, j+5, k+9, ModBlock.appleTreeLeaves, 0, 0);
		world.setBlock(i+1, j+5, k+9, ModBlock.appleTreeLeaves, 0, 0);
		world.setBlock(i+2, j+5, k+9, ModBlock.appleTreeLeaves, 0, 0);
		world.setBlock(i+3, j+5, k+9, ModBlock.appleTreeLeaves, 0, 0);
		world.setBlock(i+4, j+5, k+9, ModBlock.appleTreeLeaves, 0, 0);
		world.setBlock(i+5, j+5, k+9, Block.getBlockById(17), 8, 2);
		world.setBlock(i+6, j+5, k+9, ModBlock.appleTreeLeaves, 0, 0);
		world.setBlock(i+7, j+5, k+9, ModBlock.appleTreeLeaves, 0, 0);
		world.setBlock(i+8, j+5, k+9, ModBlock.appleTreeLeaves, 0, 0);
		world.setBlock(i+9, j+5, k+9, ModBlock.appleTreeLeaves, 0, 0);
		world.setBlock(i+10, j+5, k+9, ModBlock.appleTreeLeaves, 0, 0);
		world.setBlock(i+0, j+5, k+10, ModBlock.appleTreeLeaves, 0, 0);
		world.setBlock(i+1, j+5, k+10, ModBlock.appleTreeLeaves, 0, 0);
		world.setBlock(i+2, j+5, k+10, ModBlock.appleTreeLeaves, 0, 0);
		world.setBlock(i+3, j+5, k+10, ModBlock.appleTreeLeaves, 0, 0);
		world.setBlock(i+4, j+5, k+10, ModBlock.appleTreeLeaves, 0, 0);
		world.setBlock(i+5, j+5, k+10, ModBlock.appleTreeLeaves, 0, 0);
		world.setBlock(i+6, j+5, k+10, ModBlock.appleTreeLeaves, 0, 0);
		world.setBlock(i+7, j+5, k+10, ModBlock.appleTreeLeaves, 0, 0);
		world.setBlock(i+8, j+5, k+10, ModBlock.appleTreeLeaves, 0, 0);
		world.setBlock(i+9, j+5, k+10, ModBlock.appleTreeLeaves, 0, 0);
		world.setBlock(i+10, j+5, k+10, ModBlock.appleTreeLeaves, 0, 0);
		world.setBlock(i+0, j+6, k+0, ModBlock.appleTreeLeaves, 0, 0);
		world.setBlock(i+1, j+6, k+0, ModBlock.appleTreeLeaves, 0, 0);
		world.setBlock(i+2, j+6, k+0, ModBlock.appleTreeLeaves, 0, 0);
		world.setBlock(i+3, j+6, k+0, ModBlock.appleTreeLeaves, 0, 0);
		world.setBlock(i+4, j+6, k+0, ModBlock.appleTreeLeaves, 0, 0);
		world.setBlock(i+5, j+6, k+0, ModBlock.appleTreeLeaves, 0, 0);
		world.setBlock(i+6, j+6, k+0, ModBlock.appleTreeLeaves, 0, 0);
		world.setBlock(i+7, j+6, k+0, ModBlock.appleTreeLeaves, 0, 0);
		world.setBlock(i+8, j+6, k+0, ModBlock.appleTreeLeaves, 0, 0);
		world.setBlock(i+9, j+6, k+0, ModBlock.appleTreeLeaves, 0, 0);
		world.setBlock(i+10, j+6, k+0, ModBlock.appleTreeLeaves, 0, 0);
		world.setBlock(i+0, j+6, k+1, ModBlock.appleTreeLeaves, 0, 0);
		world.setBlock(i+1, j+6, k+1, ModBlock.appleTreeLeaves, 0, 0);
		world.setBlock(i+2, j+6, k+1, ModBlock.appleTreeLeaves, 0, 0);
		world.setBlock(i+3, j+6, k+1, ModBlock.appleTreeLeaves, 0, 0);
		world.setBlock(i+4, j+6, k+1, ModBlock.appleTreeLeaves, 0, 0);
		world.setBlock(i+5, j+6, k+1, ModBlock.appleTreeLeaves, 0, 0);
		world.setBlock(i+6, j+6, k+1, ModBlock.appleTreeLeaves, 0, 0);
		world.setBlock(i+7, j+6, k+1, ModBlock.appleTreeLeaves, 0, 0);
		world.setBlock(i+8, j+6, k+1, ModBlock.appleTreeLeaves, 0, 0);
		world.setBlock(i+9, j+6, k+1, ModBlock.appleTreeLeaves, 0, 0);
		world.setBlock(i+10, j+6, k+1, ModBlock.appleTreeLeaves, 0, 0);
		world.setBlock(i+0, j+6, k+2, ModBlock.appleTreeLeaves, 0, 0);
		world.setBlock(i+1, j+6, k+2, ModBlock.appleTreeLeaves, 0, 0);
		world.setBlock(i+2, j+6, k+2, ModBlock.appleTreeLeaves, 0, 0);
		world.setBlock(i+3, j+6, k+2, ModBlock.appleTreeLeaves, 0, 0);
		world.setBlock(i+4, j+6, k+2, ModBlock.appleTreeLeaves, 0, 0);
		world.setBlock(i+5, j+6, k+2, ModBlock.appleTreeLeaves, 0, 0);
		world.setBlock(i+6, j+6, k+2, ModBlock.appleTreeLeaves, 0, 0);
		world.setBlock(i+7, j+6, k+2, ModBlock.appleTreeLeaves, 0, 0);
		world.setBlock(i+8, j+6, k+2, ModBlock.appleTreeLeaves, 0, 0);
		world.setBlock(i+9, j+6, k+2, ModBlock.appleTreeLeaves, 0, 0);
		world.setBlock(i+10, j+6, k+2, ModBlock.appleTreeLeaves, 0, 0);
		world.setBlock(i+0, j+6, k+3, ModBlock.appleTreeLeaves, 0, 0);
		world.setBlock(i+1, j+6, k+3, ModBlock.appleTreeLeaves, 0, 0);
		world.setBlock(i+2, j+6, k+3, ModBlock.appleTreeLeaves, 0, 0);
		world.setBlock(i+3, j+6, k+3, ModBlock.appleTreeLeaves, 0, 0);
		world.setBlock(i+4, j+6, k+3, ModBlock.appleTreeLeaves, 0, 0);
		world.setBlock(i+5, j+6, k+3, ModBlock.appleTreeLeaves, 0, 0);
		world.setBlock(i+6, j+6, k+3, ModBlock.appleTreeLeaves, 0, 0);
		world.setBlock(i+7, j+6, k+3, ModBlock.appleTreeLeaves, 0, 0);
		world.setBlock(i+8, j+6, k+3, ModBlock.appleTreeLeaves, 0, 0);
		world.setBlock(i+9, j+6, k+3, ModBlock.appleTreeLeaves, 0, 0);
		world.setBlock(i+10, j+6, k+3, ModBlock.appleTreeLeaves, 0, 0);
		world.setBlock(i+0, j+6, k+4, ModBlock.appleTreeLeaves, 0, 0);
		world.setBlock(i+1, j+6, k+4, ModBlock.appleTreeLeaves, 0, 0);
		world.setBlock(i+2, j+6, k+4, ModBlock.appleTreeLeaves, 0, 0);
		world.setBlock(i+3, j+6, k+4, ModBlock.appleTreeLeaves, 0, 0);
		world.setBlock(i+4, j+6, k+4, ModBlock.appleTreeLeaves, 0, 0);
		world.setBlock(i+5, j+6, k+4, ModBlock.appleTreeLeaves, 0, 0);
		world.setBlock(i+6, j+6, k+4, ModBlock.appleTreeLeaves, 0, 0);
		world.setBlock(i+7, j+6, k+4, ModBlock.appleTreeLeaves, 0, 0);
		world.setBlock(i+8, j+6, k+4, ModBlock.appleTreeLeaves, 0, 0);
		world.setBlock(i+9, j+6, k+4, ModBlock.appleTreeLeaves, 0, 0);
		world.setBlock(i+10, j+6, k+4, ModBlock.appleTreeLeaves, 0, 0);
		world.setBlock(i+0, j+6, k+5, ModBlock.appleTreeLeaves, 0, 0);
		world.setBlock(i+1, j+6, k+5, ModBlock.appleTreeLeaves, 0, 0);
		world.setBlock(i+2, j+6, k+5, ModBlock.appleTreeLeaves, 0, 0);
		world.setBlock(i+3, j+6, k+5, ModBlock.appleTreeLeaves, 0, 0);
		world.setBlock(i+4, j+6, k+5, ModBlock.appleTreeLeaves, 0, 0);
		world.setBlock(i+5, j+6, k+5, ModBlock.appleTreeLeaves, 0, 0);
		world.setBlock(i+6, j+6, k+5, ModBlock.appleTreeLeaves, 0, 0);
		world.setBlock(i+7, j+6, k+5, ModBlock.appleTreeLeaves, 0, 0);
		world.setBlock(i+8, j+6, k+5, ModBlock.appleTreeLeaves, 0, 0);
		world.setBlock(i+9, j+6, k+5, ModBlock.appleTreeLeaves, 0, 0);
		world.setBlock(i+10, j+6, k+5, ModBlock.appleTreeLeaves, 0, 0);
		world.setBlock(i+0, j+6, k+6, ModBlock.appleTreeLeaves, 0, 0);
		world.setBlock(i+1, j+6, k+6, ModBlock.appleTreeLeaves, 0, 0);
		world.setBlock(i+2, j+6, k+6, ModBlock.appleTreeLeaves, 0, 0);
		world.setBlock(i+3, j+6, k+6, ModBlock.appleTreeLeaves, 0, 0);
		world.setBlock(i+4, j+6, k+6, ModBlock.appleTreeLeaves, 0, 0);
		world.setBlock(i+5, j+6, k+6, ModBlock.appleTreeLeaves, 0, 0);
		world.setBlock(i+6, j+6, k+6, ModBlock.appleTreeLeaves, 0, 0);
		world.setBlock(i+7, j+6, k+6, ModBlock.appleTreeLeaves, 0, 0);
		world.setBlock(i+8, j+6, k+6, ModBlock.appleTreeLeaves, 0, 0);
		world.setBlock(i+9, j+6, k+6, ModBlock.appleTreeLeaves, 0, 0);
		world.setBlock(i+10, j+6, k+6, ModBlock.appleTreeLeaves, 0, 0);
		world.setBlock(i+0, j+6, k+7, ModBlock.appleTreeLeaves, 0, 0);
		world.setBlock(i+1, j+6, k+7, ModBlock.appleTreeLeaves, 0, 0);
		world.setBlock(i+2, j+6, k+7, ModBlock.appleTreeLeaves, 0, 0);
		world.setBlock(i+3, j+6, k+7, ModBlock.appleTreeLeaves, 0, 0);
		world.setBlock(i+4, j+6, k+7, ModBlock.appleTreeLeaves, 0, 0);
		world.setBlock(i+5, j+6, k+7, ModBlock.appleTreeLeaves, 0, 0);
		world.setBlock(i+6, j+6, k+7, ModBlock.appleTreeLeaves, 0, 0);
		world.setBlock(i+7, j+6, k+7, ModBlock.appleTreeLeaves, 0, 0);
		world.setBlock(i+8, j+6, k+7, ModBlock.appleTreeLeaves, 0, 0);
		world.setBlock(i+9, j+6, k+7, ModBlock.appleTreeLeaves, 0, 0);
		world.setBlock(i+10, j+6, k+7, ModBlock.appleTreeLeaves, 0, 0);
		world.setBlock(i+0, j+6, k+8, ModBlock.appleTreeLeaves, 0, 0);
		world.setBlock(i+1, j+6, k+8, ModBlock.appleTreeLeaves, 0, 0);
		world.setBlock(i+2, j+6, k+8, ModBlock.appleTreeLeaves, 0, 0);
		world.setBlock(i+3, j+6, k+8, ModBlock.appleTreeLeaves, 0, 0);
		world.setBlock(i+4, j+6, k+8, ModBlock.appleTreeLeaves, 0, 0);
		world.setBlock(i+5, j+6, k+8, ModBlock.appleTreeLeaves, 0, 0);
		world.setBlock(i+6, j+6, k+8, ModBlock.appleTreeLeaves, 0, 0);
		world.setBlock(i+7, j+6, k+8, ModBlock.appleTreeLeaves, 0, 0);
		world.setBlock(i+8, j+6, k+8, ModBlock.appleTreeLeaves, 0, 0);
		world.setBlock(i+9, j+6, k+8, ModBlock.appleTreeLeaves, 0, 0);
		world.setBlock(i+10, j+6, k+8, ModBlock.appleTreeLeaves, 0, 0);
		world.setBlock(i+0, j+6, k+9, ModBlock.appleTreeLeaves, 0, 0);
		world.setBlock(i+1, j+6, k+9, ModBlock.appleTreeLeaves, 0, 0);
		world.setBlock(i+2, j+6, k+9, ModBlock.appleTreeLeaves, 0, 0);
		world.setBlock(i+3, j+6, k+9, ModBlock.appleTreeLeaves, 0, 0);
		world.setBlock(i+4, j+6, k+9, ModBlock.appleTreeLeaves, 0, 0);
		world.setBlock(i+5, j+6, k+9, ModBlock.appleTreeLeaves, 0, 0);
		world.setBlock(i+6, j+6, k+9, ModBlock.appleTreeLeaves, 0, 0);
		world.setBlock(i+7, j+6, k+9, ModBlock.appleTreeLeaves, 0, 0);
		world.setBlock(i+8, j+6, k+9, ModBlock.appleTreeLeaves, 0, 0);
		world.setBlock(i+9, j+6, k+9, ModBlock.appleTreeLeaves, 0, 0);
		world.setBlock(i+10, j+6, k+9, ModBlock.appleTreeLeaves, 0, 0);
		world.setBlock(i+0, j+6, k+10, ModBlock.appleTreeLeaves, 0, 0);
		world.setBlock(i+1, j+6, k+10, ModBlock.appleTreeLeaves, 0, 0);
		world.setBlock(i+2, j+6, k+10, ModBlock.appleTreeLeaves, 0, 0);
		world.setBlock(i+3, j+6, k+10, ModBlock.appleTreeLeaves, 0, 0);
		world.setBlock(i+4, j+6, k+10, ModBlock.appleTreeLeaves, 0, 0);
		world.setBlock(i+5, j+6, k+10, ModBlock.appleTreeLeaves, 0, 0);
		world.setBlock(i+6, j+6, k+10, ModBlock.appleTreeLeaves, 0, 0);
		world.setBlock(i+7, j+6, k+10, ModBlock.appleTreeLeaves, 0, 0);
		world.setBlock(i+8, j+6, k+10, ModBlock.appleTreeLeaves, 0, 0);
		world.setBlock(i+9, j+6, k+10, ModBlock.appleTreeLeaves, 0, 0);
		world.setBlock(i+10, j+6, k+10, ModBlock.appleTreeLeaves, 0, 0);
		world.setBlock(i+0, j+7, k+0, ModBlock.appleTreeLeaves, 0, 0);
		world.setBlock(i+1, j+7, k+0, ModBlock.appleTreeLeaves, 0, 0);
		world.setBlock(i+2, j+7, k+0, ModBlock.appleTreeLeaves, 0, 0);
		world.setBlock(i+3, j+7, k+0, ModBlock.appleTreeLeaves, 0, 0);
		world.setBlock(i+4, j+7, k+0, ModBlock.appleTreeLeaves, 0, 0);
		world.setBlock(i+5, j+7, k+0, ModBlock.appleTreeLeaves, 0, 0);
		world.setBlock(i+6, j+7, k+0, ModBlock.appleTreeLeaves, 0, 0);
		world.setBlock(i+7, j+7, k+0, ModBlock.appleTreeLeaves, 0, 0);
		world.setBlock(i+8, j+7, k+0, ModBlock.appleTreeLeaves, 0, 0);
		world.setBlock(i+9, j+7, k+0, ModBlock.appleTreeLeaves, 0, 0);
		world.setBlock(i+10, j+7, k+0, ModBlock.appleTreeLeaves, 0, 0);
		world.setBlock(i+0, j+7, k+1, ModBlock.appleTreeLeaves, 0, 0);
		world.setBlock(i+1, j+7, k+1, ModBlock.appleTreeLeaves, 0, 0);
		world.setBlock(i+2, j+7, k+1, ModBlock.appleTreeLeaves, 0, 0);
		world.setBlock(i+3, j+7, k+1, ModBlock.appleTreeLeaves, 0, 0);
		world.setBlock(i+4, j+7, k+1, ModBlock.appleTreeLeaves, 0, 0);
		world.setBlock(i+5, j+7, k+1, ModBlock.appleTreeLeaves, 0, 0);
		world.setBlock(i+6, j+7, k+1, ModBlock.appleTreeLeaves, 0, 0);
		world.setBlock(i+7, j+7, k+1, ModBlock.appleTreeLeaves, 0, 0);
		world.setBlock(i+8, j+7, k+1, ModBlock.appleTreeLeaves, 0, 0);
		world.setBlock(i+9, j+7, k+1, ModBlock.appleTreeLeaves, 0, 0);
		world.setBlock(i+10, j+7, k+1, ModBlock.appleTreeLeaves, 0, 0);
		world.setBlock(i+0, j+7, k+2, ModBlock.appleTreeLeaves, 0, 0);
		world.setBlock(i+1, j+7, k+2, ModBlock.appleTreeLeaves, 0, 0);
		world.setBlock(i+2, j+7, k+2, ModBlock.appleTreeLeaves, 0, 0);
		world.setBlock(i+3, j+7, k+2, ModBlock.appleTreeLeaves, 0, 0);
		world.setBlock(i+4, j+7, k+2, ModBlock.appleTreeLeaves, 0, 0);
		world.setBlock(i+5, j+7, k+2, ModBlock.appleTreeLeaves, 0, 0);
		world.setBlock(i+6, j+7, k+2, ModBlock.appleTreeLeaves, 0, 0);
		world.setBlock(i+7, j+7, k+2, ModBlock.appleTreeLeaves, 0, 0);
		world.setBlock(i+8, j+7, k+2, ModBlock.appleTreeLeaves, 0, 0);
		world.setBlock(i+9, j+7, k+2, ModBlock.appleTreeLeaves, 0, 0);
		world.setBlock(i+10, j+7, k+2, ModBlock.appleTreeLeaves, 0, 0);
		world.setBlock(i+0, j+7, k+3, ModBlock.appleTreeLeaves, 0, 0);
		world.setBlock(i+1, j+7, k+3, ModBlock.appleTreeLeaves, 0, 0);
		world.setBlock(i+2, j+7, k+3, ModBlock.appleTreeLeaves, 0, 0);
		world.setBlock(i+3, j+7, k+3, ModBlock.appleTreeLeaves, 0, 0);
		world.setBlock(i+4, j+7, k+3, ModBlock.appleTreeLeaves, 0, 0);
		world.setBlock(i+5, j+7, k+3, ModBlock.appleTreeLeaves, 0, 0);
		world.setBlock(i+6, j+7, k+3, ModBlock.appleTreeLeaves, 0, 0);
		world.setBlock(i+7, j+7, k+3, ModBlock.appleTreeLeaves, 0, 0);
		world.setBlock(i+8, j+7, k+3, ModBlock.appleTreeLeaves, 0, 0);
		world.setBlock(i+9, j+7, k+3, ModBlock.appleTreeLeaves, 0, 0);
		world.setBlock(i+10, j+7, k+3, ModBlock.appleTreeLeaves, 0, 0);
		world.setBlock(i+0, j+7, k+4, ModBlock.appleTreeLeaves, 0, 0);
		world.setBlock(i+1, j+7, k+4, ModBlock.appleTreeLeaves, 0, 0);
		world.setBlock(i+2, j+7, k+4, ModBlock.appleTreeLeaves, 0, 0);
		world.setBlock(i+3, j+7, k+4, ModBlock.appleTreeLeaves, 0, 0);
		world.setBlock(i+4, j+7, k+4, ModBlock.appleTreeLeaves, 0, 0);
		world.setBlock(i+5, j+7, k+4, ModBlock.appleTreeLeaves, 0, 0);
		world.setBlock(i+6, j+7, k+4, ModBlock.appleTreeLeaves, 0, 0);
		world.setBlock(i+7, j+7, k+4, ModBlock.appleTreeLeaves, 0, 0);
		world.setBlock(i+8, j+7, k+4, ModBlock.appleTreeLeaves, 0, 0);
		world.setBlock(i+9, j+7, k+4, ModBlock.appleTreeLeaves, 0, 0);
		world.setBlock(i+10, j+7, k+4, ModBlock.appleTreeLeaves, 0, 0);
		world.setBlock(i+0, j+7, k+5, ModBlock.appleTreeLeaves, 0, 0);
		world.setBlock(i+1, j+7, k+5, ModBlock.appleTreeLeaves, 0, 0);
		world.setBlock(i+2, j+7, k+5, ModBlock.appleTreeLeaves, 0, 0);
		world.setBlock(i+3, j+7, k+5, ModBlock.appleTreeLeaves, 0, 0);
		world.setBlock(i+4, j+7, k+5, ModBlock.appleTreeLeaves, 0, 0);
		world.setBlock(i+5, j+7, k+5, ModBlock.appleTreeLeaves, 0, 0);
		world.setBlock(i+6, j+7, k+5, ModBlock.appleTreeLeaves, 0, 0);
		world.setBlock(i+7, j+7, k+5, ModBlock.appleTreeLeaves, 0, 0);
		world.setBlock(i+8, j+7, k+5, ModBlock.appleTreeLeaves, 0, 0);
		world.setBlock(i+9, j+7, k+5, ModBlock.appleTreeLeaves, 0, 0);
		world.setBlock(i+10, j+7, k+5, ModBlock.appleTreeLeaves, 0, 0);
		world.setBlock(i+0, j+7, k+6, ModBlock.appleTreeLeaves, 0, 0);
		world.setBlock(i+1, j+7, k+6, ModBlock.appleTreeLeaves, 0, 0);
		world.setBlock(i+2, j+7, k+6, ModBlock.appleTreeLeaves, 0, 0);
		world.setBlock(i+3, j+7, k+6, ModBlock.appleTreeLeaves, 0, 0);
		world.setBlock(i+4, j+7, k+6, ModBlock.appleTreeLeaves, 0, 0);
		world.setBlock(i+5, j+7, k+6, ModBlock.appleTreeLeaves, 0, 0);
		world.setBlock(i+6, j+7, k+6, ModBlock.appleTreeLeaves, 0, 0);
		world.setBlock(i+7, j+7, k+6, ModBlock.appleTreeLeaves, 0, 0);
		world.setBlock(i+8, j+7, k+6, ModBlock.appleTreeLeaves, 0, 0);
		world.setBlock(i+9, j+7, k+6, ModBlock.appleTreeLeaves, 0, 0);
		world.setBlock(i+10, j+7, k+6, ModBlock.appleTreeLeaves, 0, 0);
		world.setBlock(i+0, j+7, k+7, ModBlock.appleTreeLeaves, 0, 0);
		world.setBlock(i+1, j+7, k+7, ModBlock.appleTreeLeaves, 0, 0);
		world.setBlock(i+2, j+7, k+7, ModBlock.appleTreeLeaves, 0, 0);
		world.setBlock(i+3, j+7, k+7, ModBlock.appleTreeLeaves, 0, 0);
		world.setBlock(i+4, j+7, k+7, ModBlock.appleTreeLeaves, 0, 0);
		world.setBlock(i+5, j+7, k+7, ModBlock.appleTreeLeaves, 0, 0);
		world.setBlock(i+6, j+7, k+7, ModBlock.appleTreeLeaves, 0, 0);
		world.setBlock(i+7, j+7, k+7, ModBlock.appleTreeLeaves, 0, 0);
		world.setBlock(i+8, j+7, k+7, ModBlock.appleTreeLeaves, 0, 0);
		world.setBlock(i+9, j+7, k+7, ModBlock.appleTreeLeaves, 0, 0);
		world.setBlock(i+10, j+7, k+7, ModBlock.appleTreeLeaves, 0, 0);
		world.setBlock(i+0, j+7, k+8, ModBlock.appleTreeLeaves, 0, 0);
		world.setBlock(i+1, j+7, k+8, ModBlock.appleTreeLeaves, 0, 0);
		world.setBlock(i+2, j+7, k+8, ModBlock.appleTreeLeaves, 0, 0);
		world.setBlock(i+3, j+7, k+8, ModBlock.appleTreeLeaves, 0, 0);
		world.setBlock(i+4, j+7, k+8, ModBlock.appleTreeLeaves, 0, 0);
		world.setBlock(i+5, j+7, k+8, ModBlock.appleTreeLeaves, 0, 0);
		world.setBlock(i+6, j+7, k+8, ModBlock.appleTreeLeaves, 0, 0);
		world.setBlock(i+7, j+7, k+8, ModBlock.appleTreeLeaves, 0, 0);
		world.setBlock(i+8, j+7, k+8, ModBlock.appleTreeLeaves, 0, 0);
		world.setBlock(i+9, j+7, k+8, ModBlock.appleTreeLeaves, 0, 0);
		world.setBlock(i+10, j+7, k+8, ModBlock.appleTreeLeaves, 0, 0);
		world.setBlock(i+0, j+7, k+9, ModBlock.appleTreeLeaves, 0, 0);
		world.setBlock(i+1, j+7, k+9, ModBlock.appleTreeLeaves, 0, 0);
		world.setBlock(i+2, j+7, k+9, ModBlock.appleTreeLeaves, 0, 0);
		world.setBlock(i+3, j+7, k+9, ModBlock.appleTreeLeaves, 0, 0);
		world.setBlock(i+4, j+7, k+9, ModBlock.appleTreeLeaves, 0, 0);
		world.setBlock(i+5, j+7, k+9, ModBlock.appleTreeLeaves, 0, 0);
		world.setBlock(i+6, j+7, k+9, ModBlock.appleTreeLeaves, 0, 0);
		world.setBlock(i+7, j+7, k+9, ModBlock.appleTreeLeaves, 0, 0);
		world.setBlock(i+8, j+7, k+9, ModBlock.appleTreeLeaves, 0, 0);
		world.setBlock(i+9, j+7, k+9, ModBlock.appleTreeLeaves, 0, 0);
		world.setBlock(i+10, j+7, k+9, ModBlock.appleTreeLeaves, 0, 0);
		world.setBlock(i+0, j+7, k+10, ModBlock.appleTreeLeaves, 0, 0);
		world.setBlock(i+1, j+7, k+10, ModBlock.appleTreeLeaves, 0, 0);
		world.setBlock(i+2, j+7, k+10, ModBlock.appleTreeLeaves, 0, 0);
		world.setBlock(i+3, j+7, k+10, ModBlock.appleTreeLeaves, 0, 0);
		world.setBlock(i+4, j+7, k+10, ModBlock.appleTreeLeaves, 0, 0);
		world.setBlock(i+5, j+7, k+10, ModBlock.appleTreeLeaves, 0, 0);
		world.setBlock(i+6, j+7, k+10, ModBlock.appleTreeLeaves, 0, 0);
		world.setBlock(i+7, j+7, k+10, ModBlock.appleTreeLeaves, 0, 0);
		world.setBlock(i+8, j+7, k+10, ModBlock.appleTreeLeaves, 0, 0);
		world.setBlock(i+9, j+7, k+10, ModBlock.appleTreeLeaves, 0, 0);
		world.setBlock(i+10, j+7, k+10, ModBlock.appleTreeLeaves, 0, 0);
		world.setBlock(i+0, j+8, k+0, ModBlock.appleTreeLeaves, 0, 0);
		world.setBlock(i+1, j+8, k+0, ModBlock.appleTreeLeaves, 0, 0);
		world.setBlock(i+2, j+8, k+0, ModBlock.appleTreeLeaves, 0, 0);
		world.setBlock(i+3, j+8, k+0, ModBlock.appleTreeLeaves, 0, 0);
		world.setBlock(i+4, j+8, k+0, ModBlock.appleTreeLeaves, 0, 0);
		world.setBlock(i+5, j+8, k+0, ModBlock.appleTreeLeaves, 0, 0);
		world.setBlock(i+6, j+8, k+0, ModBlock.appleTreeLeaves, 0, 0);
		world.setBlock(i+7, j+8, k+0, ModBlock.appleTreeLeaves, 0, 0);
		world.setBlock(i+8, j+8, k+0, ModBlock.appleTreeLeaves, 0, 0);
		world.setBlock(i+9, j+8, k+0, ModBlock.appleTreeLeaves, 0, 0);
		world.setBlock(i+10, j+8, k+0, ModBlock.appleTreeLeaves, 0, 0);
		world.setBlock(i+0, j+8, k+1, ModBlock.appleTreeLeaves, 0, 0);
		world.setBlock(i+1, j+8, k+1, ModBlock.appleTreeLeaves, 0, 0);
		world.setBlock(i+2, j+8, k+1, ModBlock.appleTreeLeaves, 0, 0);
		world.setBlock(i+3, j+8, k+1, ModBlock.appleTreeLeaves, 0, 0);
		world.setBlock(i+4, j+8, k+1, ModBlock.appleTreeLeaves, 0, 0);
		world.setBlock(i+5, j+8, k+1, ModBlock.appleTreeLeaves, 0, 0);
		world.setBlock(i+6, j+8, k+1, ModBlock.appleTreeLeaves, 0, 0);
		world.setBlock(i+7, j+8, k+1, ModBlock.appleTreeLeaves, 0, 0);
		world.setBlock(i+8, j+8, k+1, ModBlock.appleTreeLeaves, 0, 0);
		world.setBlock(i+9, j+8, k+1, ModBlock.appleTreeLeaves, 0, 0);
		world.setBlock(i+10, j+8, k+1, ModBlock.appleTreeLeaves, 0, 0);
		world.setBlock(i+0, j+8, k+2, ModBlock.appleTreeLeaves, 0, 0);
		world.setBlock(i+1, j+8, k+2, ModBlock.appleTreeLeaves, 0, 0);
		world.setBlock(i+2, j+8, k+2, ModBlock.appleTreeLeaves, 0, 0);
		world.setBlock(i+3, j+8, k+2, ModBlock.appleTreeLeaves, 0, 0);
		world.setBlock(i+4, j+8, k+2, ModBlock.appleTreeLeaves, 0, 0);
		world.setBlock(i+5, j+8, k+2, ModBlock.appleTreeLeaves, 0, 0);
		world.setBlock(i+6, j+8, k+2, ModBlock.appleTreeLeaves, 0, 0);
		world.setBlock(i+7, j+8, k+2, ModBlock.appleTreeLeaves, 0, 0);
		world.setBlock(i+8, j+8, k+2, ModBlock.appleTreeLeaves, 0, 0);
		world.setBlock(i+9, j+8, k+2, ModBlock.appleTreeLeaves, 0, 0);
		world.setBlock(i+10, j+8, k+2, ModBlock.appleTreeLeaves, 0, 0);
		world.setBlock(i+0, j+8, k+3, ModBlock.appleTreeLeaves, 0, 0);
		world.setBlock(i+1, j+8, k+3, ModBlock.appleTreeLeaves, 0, 0);
		world.setBlock(i+2, j+8, k+3, ModBlock.appleTreeLeaves, 0, 0);
		world.setBlock(i+3, j+8, k+3, ModBlock.appleTreeLeaves, 0, 0);
		world.setBlock(i+4, j+8, k+3, ModBlock.appleTreeLeaves, 0, 0);
		world.setBlock(i+5, j+8, k+3, ModBlock.appleTreeLeaves, 0, 0);
		world.setBlock(i+6, j+8, k+3, ModBlock.appleTreeLeaves, 0, 0);
		world.setBlock(i+7, j+8, k+3, ModBlock.appleTreeLeaves, 0, 0);
		world.setBlock(i+8, j+8, k+3, ModBlock.appleTreeLeaves, 0, 0);
		world.setBlock(i+9, j+8, k+3, ModBlock.appleTreeLeaves, 0, 0);
		world.setBlock(i+10, j+8, k+3, ModBlock.appleTreeLeaves, 0, 0);
		world.setBlock(i+0, j+8, k+4, ModBlock.appleTreeLeaves, 0, 0);
		world.setBlock(i+1, j+8, k+4, ModBlock.appleTreeLeaves, 0, 0);
		world.setBlock(i+2, j+8, k+4, ModBlock.appleTreeLeaves, 0, 0);
		world.setBlock(i+3, j+8, k+4, ModBlock.appleTreeLeaves, 0, 0);
		world.setBlock(i+4, j+8, k+4, ModBlock.appleTreeLeaves, 0, 0);
		world.setBlock(i+5, j+8, k+4, ModBlock.appleTreeLeaves, 0, 0);
		world.setBlock(i+6, j+8, k+4, ModBlock.appleTreeLeaves, 0, 0);
		world.setBlock(i+7, j+8, k+4, ModBlock.appleTreeLeaves, 0, 0);
		world.setBlock(i+8, j+8, k+4, ModBlock.appleTreeLeaves, 0, 0);
		world.setBlock(i+9, j+8, k+4, ModBlock.appleTreeLeaves, 0, 0);
		world.setBlock(i+10, j+8, k+4, ModBlock.appleTreeLeaves, 0, 0);
		world.setBlock(i+0, j+8, k+5, ModBlock.appleTreeLeaves, 0, 0);
		world.setBlock(i+1, j+8, k+5, ModBlock.appleTreeLeaves, 0, 0);
		world.setBlock(i+2, j+8, k+5, ModBlock.appleTreeLeaves, 0, 0);
		world.setBlock(i+3, j+8, k+5, ModBlock.appleTreeLeaves, 0, 0);
		world.setBlock(i+4, j+8, k+5, ModBlock.appleTreeLeaves, 0, 0);
		world.setBlock(i+5, j+8, k+5, ModBlock.appleTreeLeaves, 0, 0);
		world.setBlock(i+6, j+8, k+5, ModBlock.appleTreeLeaves, 0, 0);
		world.setBlock(i+7, j+8, k+5, ModBlock.appleTreeLeaves, 0, 0);
		world.setBlock(i+8, j+8, k+5, ModBlock.appleTreeLeaves, 0, 0);
		world.setBlock(i+9, j+8, k+5, ModBlock.appleTreeLeaves, 0, 0);
		world.setBlock(i+10, j+8, k+5, ModBlock.appleTreeLeaves, 0, 0);
		world.setBlock(i+0, j+8, k+6, ModBlock.appleTreeLeaves, 0, 0);
		world.setBlock(i+1, j+8, k+6, ModBlock.appleTreeLeaves, 0, 0);
		world.setBlock(i+2, j+8, k+6, ModBlock.appleTreeLeaves, 0, 0);
		world.setBlock(i+3, j+8, k+6, ModBlock.appleTreeLeaves, 0, 0);
		world.setBlock(i+4, j+8, k+6, ModBlock.appleTreeLeaves, 0, 0);
		world.setBlock(i+5, j+8, k+6, ModBlock.appleTreeLeaves, 0, 0);
		world.setBlock(i+6, j+8, k+6, ModBlock.appleTreeLeaves, 0, 0);
		world.setBlock(i+7, j+8, k+6, ModBlock.appleTreeLeaves, 0, 0);
		world.setBlock(i+8, j+8, k+6, ModBlock.appleTreeLeaves, 0, 0);
		world.setBlock(i+9, j+8, k+6, ModBlock.appleTreeLeaves, 0, 0);
		world.setBlock(i+10, j+8, k+6, ModBlock.appleTreeLeaves, 0, 0);
		world.setBlock(i+0, j+8, k+7, ModBlock.appleTreeLeaves, 0, 0);
		world.setBlock(i+1, j+8, k+7, ModBlock.appleTreeLeaves, 0, 0);
		world.setBlock(i+2, j+8, k+7, ModBlock.appleTreeLeaves, 0, 0);
		world.setBlock(i+3, j+8, k+7, ModBlock.appleTreeLeaves, 0, 0);
		world.setBlock(i+4, j+8, k+7, ModBlock.appleTreeLeaves, 0, 0);
		world.setBlock(i+5, j+8, k+7, ModBlock.appleTreeLeaves, 0, 0);
		world.setBlock(i+6, j+8, k+7, ModBlock.appleTreeLeaves, 0, 0);
		world.setBlock(i+7, j+8, k+7, ModBlock.appleTreeLeaves, 0, 0);
		world.setBlock(i+8, j+8, k+7, ModBlock.appleTreeLeaves, 0, 0);
		world.setBlock(i+9, j+8, k+7, ModBlock.appleTreeLeaves, 0, 0);
		world.setBlock(i+10, j+8, k+7, ModBlock.appleTreeLeaves, 0, 0);
		world.setBlock(i+0, j+8, k+8, ModBlock.appleTreeLeaves, 0, 0);
		world.setBlock(i+1, j+8, k+8, ModBlock.appleTreeLeaves, 0, 0);
		world.setBlock(i+2, j+8, k+8, ModBlock.appleTreeLeaves, 0, 0);
		world.setBlock(i+3, j+8, k+8, ModBlock.appleTreeLeaves, 0, 0);
		world.setBlock(i+4, j+8, k+8, ModBlock.appleTreeLeaves, 0, 0);
		world.setBlock(i+5, j+8, k+8, ModBlock.appleTreeLeaves, 0, 0);
		world.setBlock(i+6, j+8, k+8, ModBlock.appleTreeLeaves, 0, 0);
		world.setBlock(i+7, j+8, k+8, ModBlock.appleTreeLeaves, 0, 0);
		world.setBlock(i+8, j+8, k+8, ModBlock.appleTreeLeaves, 0, 0);
		world.setBlock(i+9, j+8, k+8, ModBlock.appleTreeLeaves, 0, 0);
		world.setBlock(i+10, j+8, k+8, ModBlock.appleTreeLeaves, 0, 0);
		world.setBlock(i+0, j+8, k+9, ModBlock.appleTreeLeaves, 0, 0);
		world.setBlock(i+1, j+8, k+9, ModBlock.appleTreeLeaves, 0, 0);
		world.setBlock(i+2, j+8, k+9, ModBlock.appleTreeLeaves, 0, 0);
		world.setBlock(i+3, j+8, k+9, ModBlock.appleTreeLeaves, 0, 0);
		world.setBlock(i+4, j+8, k+9, ModBlock.appleTreeLeaves, 0, 0);
		world.setBlock(i+5, j+8, k+9, ModBlock.appleTreeLeaves, 0, 0);
		world.setBlock(i+6, j+8, k+9, ModBlock.appleTreeLeaves, 0, 0);
		world.setBlock(i+7, j+8, k+9, ModBlock.appleTreeLeaves, 0, 0);
		world.setBlock(i+8, j+8, k+9, ModBlock.appleTreeLeaves, 0, 0);
		world.setBlock(i+9, j+8, k+9, ModBlock.appleTreeLeaves, 0, 0);
		world.setBlock(i+10, j+8, k+9, ModBlock.appleTreeLeaves, 0, 0);
		world.setBlock(i+0, j+8, k+10, ModBlock.appleTreeLeaves, 0, 0);
		world.setBlock(i+1, j+8, k+10, ModBlock.appleTreeLeaves, 0, 0);
		world.setBlock(i+2, j+8, k+10, ModBlock.appleTreeLeaves, 0, 0);
		world.setBlock(i+3, j+8, k+10, ModBlock.appleTreeLeaves, 0, 0);
		world.setBlock(i+4, j+8, k+10, ModBlock.appleTreeLeaves, 0, 0);
		world.setBlock(i+5, j+8, k+10, ModBlock.appleTreeLeaves, 0, 0);
		world.setBlock(i+6, j+8, k+10, ModBlock.appleTreeLeaves, 0, 0);
		world.setBlock(i+7, j+8, k+10, ModBlock.appleTreeLeaves, 0, 0);
		world.setBlock(i+8, j+8, k+10, ModBlock.appleTreeLeaves, 0, 0);
		world.setBlock(i+9, j+8, k+10, ModBlock.appleTreeLeaves, 0, 0);
		world.setBlock(i+10, j+8, k+10, ModBlock.appleTreeLeaves, 0, 0);
		world.setBlock(i+0, j+9, k+0, ModBlock.appleTreeLeaves, 0, 0);
		world.setBlock(i+1, j+9, k+0, ModBlock.appleTreeLeaves, 0, 0);
		world.setBlock(i+2, j+9, k+0, ModBlock.appleTreeLeaves, 0, 0);
		world.setBlock(i+3, j+9, k+0, ModBlock.appleTreeLeaves, 0, 0);
		world.setBlock(i+4, j+9, k+0, ModBlock.appleTreeLeaves, 0, 0);
		world.setBlock(i+5, j+9, k+0, ModBlock.appleTreeLeaves, 0, 0);
		world.setBlock(i+6, j+9, k+0, ModBlock.appleTreeLeaves, 0, 0);
		world.setBlock(i+7, j+9, k+0, ModBlock.appleTreeLeaves, 0, 0);
		world.setBlock(i+8, j+9, k+0, ModBlock.appleTreeLeaves, 0, 0);
		world.setBlock(i+9, j+9, k+0, ModBlock.appleTreeLeaves, 0, 0);
		world.setBlock(i+10, j+9, k+0, ModBlock.appleTreeLeaves, 0, 0);
		world.setBlock(i+0, j+9, k+1, ModBlock.appleTreeLeaves, 0, 0);
		world.setBlock(i+1, j+9, k+1, ModBlock.appleTreeLeaves, 0, 0);
		world.setBlock(i+2, j+9, k+1, ModBlock.appleTreeLeaves, 0, 0);
		world.setBlock(i+3, j+9, k+1, ModBlock.appleTreeLeaves, 0, 0);
		world.setBlock(i+4, j+9, k+1, ModBlock.appleTreeLeaves, 0, 0);
		world.setBlock(i+5, j+9, k+1, ModBlock.appleTreeLeaves, 0, 0);
		world.setBlock(i+6, j+9, k+1, ModBlock.appleTreeLeaves, 0, 0);
		world.setBlock(i+7, j+9, k+1, ModBlock.appleTreeLeaves, 0, 0);
		world.setBlock(i+8, j+9, k+1, ModBlock.appleTreeLeaves, 0, 0);
		world.setBlock(i+9, j+9, k+1, ModBlock.appleTreeLeaves, 0, 0);
		world.setBlock(i+10, j+9, k+1, ModBlock.appleTreeLeaves, 0, 0);
		world.setBlock(i+0, j+9, k+2, ModBlock.appleTreeLeaves, 0, 0);
		world.setBlock(i+1, j+9, k+2, ModBlock.appleTreeLeaves, 0, 0);
		world.setBlock(i+2, j+9, k+2, ModBlock.appleTreeLeaves, 0, 0);
		world.setBlock(i+3, j+9, k+2, ModBlock.appleTreeLeaves, 0, 0);
		world.setBlock(i+4, j+9, k+2, ModBlock.appleTreeLeaves, 0, 0);
		world.setBlock(i+5, j+9, k+2, ModBlock.appleTreeLeaves, 0, 0);
		world.setBlock(i+6, j+9, k+2, ModBlock.appleTreeLeaves, 0, 0);
		world.setBlock(i+7, j+9, k+2, ModBlock.appleTreeLeaves, 0, 0);
		world.setBlock(i+8, j+9, k+2, ModBlock.appleTreeLeaves, 0, 0);
		world.setBlock(i+9, j+9, k+2, ModBlock.appleTreeLeaves, 0, 0);
		world.setBlock(i+10, j+9, k+2, ModBlock.appleTreeLeaves, 0, 0);
		world.setBlock(i+0, j+9, k+3, ModBlock.appleTreeLeaves, 0, 0);
		world.setBlock(i+1, j+9, k+3, ModBlock.appleTreeLeaves, 0, 0);
		world.setBlock(i+2, j+9, k+3, ModBlock.appleTreeLeaves, 0, 0);
		world.setBlock(i+3, j+9, k+3, ModBlock.appleTreeLeaves, 0, 0);
		world.setBlock(i+4, j+9, k+3, ModBlock.appleTreeLeaves, 0, 0);
		world.setBlock(i+5, j+9, k+3, ModBlock.appleTreeLeaves, 0, 0);
		world.setBlock(i+6, j+9, k+3, ModBlock.appleTreeLeaves, 0, 0);
		world.setBlock(i+7, j+9, k+3, ModBlock.appleTreeLeaves, 0, 0);
		world.setBlock(i+8, j+9, k+3, ModBlock.appleTreeLeaves, 0, 0);
		world.setBlock(i+9, j+9, k+3, ModBlock.appleTreeLeaves, 0, 0);
		world.setBlock(i+10, j+9, k+3, ModBlock.appleTreeLeaves, 0, 0);
		world.setBlock(i+0, j+9, k+4, ModBlock.appleTreeLeaves, 0, 0);
		world.setBlock(i+1, j+9, k+4, ModBlock.appleTreeLeaves, 0, 0);
		world.setBlock(i+2, j+9, k+4, ModBlock.appleTreeLeaves, 0, 0);
		world.setBlock(i+3, j+9, k+4, ModBlock.appleTreeLeaves, 0, 0);
		world.setBlock(i+4, j+9, k+4, ModBlock.appleTreeLeaves, 0, 0);
		world.setBlock(i+5, j+9, k+4, ModBlock.appleTreeLeaves, 0, 0);
		world.setBlock(i+6, j+9, k+4, ModBlock.appleTreeLeaves, 0, 0);
		world.setBlock(i+7, j+9, k+4, ModBlock.appleTreeLeaves, 0, 0);
		world.setBlock(i+8, j+9, k+4, ModBlock.appleTreeLeaves, 0, 0);
		world.setBlock(i+9, j+9, k+4, ModBlock.appleTreeLeaves, 0, 0);
		world.setBlock(i+10, j+9, k+4, ModBlock.appleTreeLeaves, 0, 0);
		world.setBlock(i+0, j+9, k+5, ModBlock.appleTreeLeaves, 0, 0);
		world.setBlock(i+1, j+9, k+5, ModBlock.appleTreeLeaves, 0, 0);
		world.setBlock(i+2, j+9, k+5, ModBlock.appleTreeLeaves, 0, 0);
		world.setBlock(i+3, j+9, k+5, ModBlock.appleTreeLeaves, 0, 0);
		world.setBlock(i+4, j+9, k+5, ModBlock.appleTreeLeaves, 0, 0);
		world.setBlock(i+5, j+9, k+5, ModBlock.appleTreeLeaves, 0, 0);
		world.setBlock(i+6, j+9, k+5, ModBlock.appleTreeLeaves, 0, 0);
		world.setBlock(i+7, j+9, k+5, ModBlock.appleTreeLeaves, 0, 0);
		world.setBlock(i+8, j+9, k+5, ModBlock.appleTreeLeaves, 0, 0);
		world.setBlock(i+9, j+9, k+5, ModBlock.appleTreeLeaves, 0, 0);
		world.setBlock(i+10, j+9, k+5, ModBlock.appleTreeLeaves, 0, 0);
		world.setBlock(i+0, j+9, k+6, ModBlock.appleTreeLeaves, 0, 0);
		world.setBlock(i+1, j+9, k+6, ModBlock.appleTreeLeaves, 0, 0);
		world.setBlock(i+2, j+9, k+6, ModBlock.appleTreeLeaves, 0, 0);
		world.setBlock(i+3, j+9, k+6, ModBlock.appleTreeLeaves, 0, 0);
		world.setBlock(i+4, j+9, k+6, ModBlock.appleTreeLeaves, 0, 0);
		world.setBlock(i+5, j+9, k+6, ModBlock.appleTreeLeaves, 0, 0);
		world.setBlock(i+6, j+9, k+6, ModBlock.appleTreeLeaves, 0, 0);
		world.setBlock(i+7, j+9, k+6, ModBlock.appleTreeLeaves, 0, 0);
		world.setBlock(i+8, j+9, k+6, ModBlock.appleTreeLeaves, 0, 0);
		world.setBlock(i+9, j+9, k+6, ModBlock.appleTreeLeaves, 0, 0);
		world.setBlock(i+10, j+9, k+6, ModBlock.appleTreeLeaves, 0, 0);
		world.setBlock(i+0, j+9, k+7, ModBlock.appleTreeLeaves, 0, 0);
		world.setBlock(i+1, j+9, k+7, ModBlock.appleTreeLeaves, 0, 0);
		world.setBlock(i+2, j+9, k+7, ModBlock.appleTreeLeaves, 0, 0);
		world.setBlock(i+3, j+9, k+7, ModBlock.appleTreeLeaves, 0, 0);
		world.setBlock(i+4, j+9, k+7, ModBlock.appleTreeLeaves, 0, 0);
		world.setBlock(i+5, j+9, k+7, ModBlock.appleTreeLeaves, 0, 0);
		world.setBlock(i+6, j+9, k+7, ModBlock.appleTreeLeaves, 0, 0);
		world.setBlock(i+7, j+9, k+7, ModBlock.appleTreeLeaves, 0, 0);
		world.setBlock(i+8, j+9, k+7, ModBlock.appleTreeLeaves, 0, 0);
		world.setBlock(i+9, j+9, k+7, ModBlock.appleTreeLeaves, 0, 0);
		world.setBlock(i+10, j+9, k+7, ModBlock.appleTreeLeaves, 0, 0);
		world.setBlock(i+0, j+9, k+8, ModBlock.appleTreeLeaves, 0, 0);
		world.setBlock(i+1, j+9, k+8, ModBlock.appleTreeLeaves, 0, 0);
		world.setBlock(i+2, j+9, k+8, ModBlock.appleTreeLeaves, 0, 0);
		world.setBlock(i+3, j+9, k+8, ModBlock.appleTreeLeaves, 0, 0);
		world.setBlock(i+4, j+9, k+8, ModBlock.appleTreeLeaves, 0, 0);
		world.setBlock(i+5, j+9, k+8, ModBlock.appleTreeLeaves, 0, 0);
		world.setBlock(i+6, j+9, k+8, ModBlock.appleTreeLeaves, 0, 0);
		world.setBlock(i+7, j+9, k+8, ModBlock.appleTreeLeaves, 0, 0);
		world.setBlock(i+8, j+9, k+8, ModBlock.appleTreeLeaves, 0, 0);
		world.setBlock(i+9, j+9, k+8, ModBlock.appleTreeLeaves, 0, 0);
		world.setBlock(i+10, j+9, k+8, ModBlock.appleTreeLeaves, 0, 0);
		world.setBlock(i+0, j+9, k+9, ModBlock.appleTreeLeaves, 0, 0);
		world.setBlock(i+1, j+9, k+9, ModBlock.appleTreeLeaves, 0, 0);
		world.setBlock(i+2, j+9, k+9, ModBlock.appleTreeLeaves, 0, 0);
		world.setBlock(i+3, j+9, k+9, ModBlock.appleTreeLeaves, 0, 0);
		world.setBlock(i+4, j+9, k+9, ModBlock.appleTreeLeaves, 0, 0);
		world.setBlock(i+5, j+9, k+9, ModBlock.appleTreeLeaves, 0, 0);
		world.setBlock(i+6, j+9, k+9, ModBlock.appleTreeLeaves, 0, 0);
		world.setBlock(i+7, j+9, k+9, ModBlock.appleTreeLeaves, 0, 0);
		world.setBlock(i+8, j+9, k+9, ModBlock.appleTreeLeaves, 0, 0);
		world.setBlock(i+9, j+9, k+9, ModBlock.appleTreeLeaves, 0, 0);
		world.setBlock(i+10, j+9, k+9, ModBlock.appleTreeLeaves, 0, 0);
		world.setBlock(i+0, j+9, k+10, ModBlock.appleTreeLeaves, 0, 0);
		world.setBlock(i+1, j+9, k+10, ModBlock.appleTreeLeaves, 0, 0);
		world.setBlock(i+2, j+9, k+10, ModBlock.appleTreeLeaves, 0, 0);
		world.setBlock(i+3, j+9, k+10, ModBlock.appleTreeLeaves, 0, 0);
		world.setBlock(i+4, j+9, k+10, ModBlock.appleTreeLeaves, 0, 0);
		world.setBlock(i+5, j+9, k+10, ModBlock.appleTreeLeaves, 0, 0);
		world.setBlock(i+6, j+9, k+10, ModBlock.appleTreeLeaves, 0, 0);
		world.setBlock(i+7, j+9, k+10, ModBlock.appleTreeLeaves, 0, 0);
		world.setBlock(i+8, j+9, k+10, ModBlock.appleTreeLeaves, 0, 0);
		world.setBlock(i+9, j+9, k+10, ModBlock.appleTreeLeaves, 0, 0);
		world.setBlock(i+10, j+9, k+10, ModBlock.appleTreeLeaves, 0, 0);
	}
}